[public:localhost] ERROR   2020-10-20 22:23:03,905 Internal Server Error: /security/tenant/register/
Traceback (most recent call last):
  File "E:\js2\DrivePWJS\ProyectosDjango3\djflow\venv\lib\site-packages\django\db\backends\utils.py", line 84, in _execute
    return self.cursor.execute(sql, params)
psycopg2.errors.NotNullViolation: el valor null para la columna «paid_until» viola la restricción not null
DETAIL:  La fila que falla contiene (3, jasmany.localhost, jasmany, jasmany, t, null, null, 2020-10-20 00:00:00+00).


The above exception was the direct cause of the following exception:

Traceback (most recent call last):
  File "E:\js2\DrivePWJS\ProyectosDjango3\djflow\venv\lib\site-packages\django\core\handlers\exception.py", line 34, in inner
    response = get_response(request)
  File "E:\js2\DrivePWJS\ProyectosDjango3\djflow\venv\lib\site-packages\django\core\handlers\base.py", line 115, in _get_response
    response = self.process_exception_by_middleware(e, request)
  File "E:\js2\DrivePWJS\ProyectosDjango3\djflow\venv\lib\site-packages\django\core\handlers\base.py", line 113, in _get_response
    response = wrapped_callback(request, *callback_args, **callback_kwargs)
  File "E:\js2\DrivePWJS\ProyectosDjango3\djflow\venv\lib\site-packages\django\views\generic\base.py", line 71, in view
    return self.dispatch(request, *args, **kwargs)
  File "E:\js2\DrivePWJS\ProyectosDjango3\djflow\venv\lib\site-packages\django\views\generic\base.py", line 97, in dispatch
    return handler(request, *args, **kwargs)
  File "E:\js2\DrivePWJS\ProyectosDjango2\djflow\djflow\apps\security\views.py", line 215, in post
    client.save()  # Ejecutar las migraciones
  File "E:\js2\DrivePWJS\ProyectosDjango3\djflow\venv\lib\site-packages\tenant_schemas\models.py", line 67, in save
    super(TenantMixin, self).save(*args, **kwargs)
  File "E:\js2\DrivePWJS\ProyectosDjango3\djflow\venv\lib\site-packages\django\db\models\base.py", line 741, in save
    force_update=force_update, update_fields=update_fields)
  File "E:\js2\DrivePWJS\ProyectosDjango3\djflow\venv\lib\site-packages\django\db\models\base.py", line 779, in save_base
    force_update, using, update_fields,
  File "E:\js2\DrivePWJS\ProyectosDjango3\djflow\venv\lib\site-packages\django\db\models\base.py", line 870, in _save_table
    result = self._do_insert(cls._base_manager, using, fields, update_pk, raw)
  File "E:\js2\DrivePWJS\ProyectosDjango3\djflow\venv\lib\site-packages\django\db\models\base.py", line 908, in _do_insert
    using=using, raw=raw)
  File "E:\js2\DrivePWJS\ProyectosDjango3\djflow\venv\lib\site-packages\django\db\models\manager.py", line 82, in manager_method
    return getattr(self.get_queryset(), name)(*args, **kwargs)
  File "E:\js2\DrivePWJS\ProyectosDjango3\djflow\venv\lib\site-packages\django\db\models\query.py", line 1186, in _insert
    return query.get_compiler(using=using).execute_sql(return_id)
  File "E:\js2\DrivePWJS\ProyectosDjango3\djflow\venv\lib\site-packages\django\db\models\sql\compiler.py", line 1332, in execute_sql
    cursor.execute(sql, params)
  File "E:\js2\DrivePWJS\ProyectosDjango3\djflow\venv\lib\site-packages\django\db\backends\utils.py", line 99, in execute
    return super().execute(sql, params)
  File "E:\js2\DrivePWJS\ProyectosDjango3\djflow\venv\lib\site-packages\django\db\backends\utils.py", line 67, in execute
    return self._execute_with_wrappers(sql, params, many=False, executor=self._execute)
  File "E:\js2\DrivePWJS\ProyectosDjango3\djflow\venv\lib\site-packages\django\db\backends\utils.py", line 76, in _execute_with_wrappers
    return executor(sql, params, many, context)
  File "E:\js2\DrivePWJS\ProyectosDjango3\djflow\venv\lib\site-packages\django\db\backends\utils.py", line 84, in _execute
    return self.cursor.execute(sql, params)
  File "E:\js2\DrivePWJS\ProyectosDjango3\djflow\venv\lib\site-packages\django\db\utils.py", line 89, in __exit__
    raise dj_exc_value.with_traceback(traceback) from exc_value
  File "E:\js2\DrivePWJS\ProyectosDjango3\djflow\venv\lib\site-packages\django\db\backends\utils.py", line 84, in _execute
    return self.cursor.execute(sql, params)
django.db.utils.IntegrityError: el valor null para la columna «paid_until» viola la restricción not null
DETAIL:  La fila que falla contiene (3, jasmany.localhost, jasmany, jasmany, t, null, null, 2020-10-20 00:00:00+00).

[public:] WARNING 2020-10-20 22:27:34,342 Not Found: /
[jasmany:jasmany.localhost] ERROR   2020-10-20 22:32:06,860 Internal Server Error: /security/login/
Traceback (most recent call last):
  File "E:\js2\DrivePWJS\ProyectosDjango3\djflow\venv\lib\site-packages\django\core\handlers\exception.py", line 34, in inner
    response = get_response(request)
  File "E:\js2\DrivePWJS\ProyectosDjango3\djflow\venv\lib\site-packages\django\core\handlers\base.py", line 115, in _get_response
    response = self.process_exception_by_middleware(e, request)
  File "E:\js2\DrivePWJS\ProyectosDjango3\djflow\venv\lib\site-packages\django\core\handlers\base.py", line 113, in _get_response
    response = wrapped_callback(request, *callback_args, **callback_kwargs)
  File "E:\js2\DrivePWJS\ProyectosDjango3\djflow\venv\lib\site-packages\django\views\generic\base.py", line 71, in view
    return self.dispatch(request, *args, **kwargs)
  File "E:\js2\DrivePWJS\ProyectosDjango3\djflow\venv\lib\site-packages\django\views\generic\base.py", line 97, in dispatch
    return handler(request, *args, **kwargs)
  File "E:\js2\DrivePWJS\ProyectosDjango2\djflow\djflow\apps\security\views.py", line 38, in get
    if request.user.is_authenticated():
TypeError: 'bool' object is not callable
[jasmany:jasmany.localhost] WARNING 2020-10-20 22:32:07,022 Not Found: /favicon.ico
